[32m2025-07-03 11:00:27 +0000[0m - dagster - [34mDEBUG[0m - load_weather_to_snowflake_job - 0b1f75af-bfda-4456-8eba-01271400bcfe - 94160 - LOGS_CAPTURED - Started capturing logs in process (pid: 94160).
[32m2025-07-03 11:00:27 +0000[0m - dagster - [34mDEBUG[0m - load_weather_to_snowflake_job - 0b1f75af-bfda-4456-8eba-01271400bcfe - 94160 - load_blob_to_snowflake - STEP_START - Started execution of step "load_blob_to_snowflake".
[32m2025-07-03 11:00:27 +0000[0m - dagster - [34mINFO[0m - load_weather_to_snowflake_job - 0b1f75af-bfda-4456-8eba-01271400bcfe - load_blob_to_snowflake - Starting load for blob: weather-2025-07-03T11-00-10.json
[32m2025-07-03 11:00:30 +0000[0m - dagster - [34mERROR[0m - [31mload_weather_to_snowflake_job - 0b1f75af-bfda-4456-8eba-01271400bcfe - 94160 - load_blob_to_snowflake - STEP_FAILURE - Execution of step "load_blob_to_snowflake" failed.

dagster._core.errors.DagsterExecutionStepExecutionError: Error occurred while executing op "load_blob_to_snowflake"::

snowflake.connector.errors.ProgrammingError: 002003 (42S02): SQL compilation error:
Table 'WEATHER_RAW' does not exist or not authorized.

Stack Trace:
  File "/usr/local/python/3.12.1/lib/python3.12/site-packages/dagster/_core/execution/plan/utils.py", line 57, in op_execution_error_boundary
    yield
  File "/usr/local/python/3.12.1/lib/python3.12/site-packages/dagster/_utils/__init__.py", line 392, in iterate_with_context
    next_output = next(iterator)
                  ^^^^^^^^^^^^^^
  File "/usr/local/python/3.12.1/lib/python3.12/site-packages/dagster/_core/execution/plan/compute_generator.py", line 137, in _coerce_op_compute_fn_to_iterator
    result = invoke_compute_fn(
             ^^^^^^^^^^^^^^^^^^
  File "/usr/local/python/3.12.1/lib/python3.12/site-packages/dagster/_core/execution/plan/compute_generator.py", line 117, in invoke_compute_fn
    return fn(context, **args_to_pass) if context_arg_provided else fn(**args_to_pass)
           ^^^^^^^^^^^^^^^^^^^^^^^^^^^
  File "/workspaces/Wheather_project/weather_proj/weather_proj/ops.py", line 36, in load_blob_to_snowflake
    cur.execute("""
  File "/usr/local/python/3.12.1/lib/python3.12/site-packages/snowflake/connector/cursor.py", line 1137, in execute
    Error.errorhandler_wrapper(self.connection, self, error_class, errvalue)
  File "/usr/local/python/3.12.1/lib/python3.12/site-packages/snowflake/connector/errors.py", line 279, in errorhandler_wrapper
    handed_over = Error.hand_to_other_handler(
                  ^^^^^^^^^^^^^^^^^^^^^^^^^^^^
  File "/usr/local/python/3.12.1/lib/python3.12/site-packages/snowflake/connector/errors.py", line 334, in hand_to_other_handler
    cursor.errorhandler(connection, cursor, error_class, error_value)
  File "/usr/local/python/3.12.1/lib/python3.12/site-packages/snowflake/connector/errors.py", line 210, in default_errorhandler
    raise error_class(
[0m
