[32m2025-07-03 10:14:19 +0000[0m - dagster - [34mDEBUG[0m - __ASSET_JOB - 2c60d167-0d55-4a4e-bd1f-c8c659d0e20e - 25415 - LOGS_CAPTURED - Started capturing logs in process (pid: 25415).
[32m2025-07-03 10:14:19 +0000[0m - dagster - [34mDEBUG[0m - __ASSET_JOB - 2c60d167-0d55-4a4e-bd1f-c8c659d0e20e - 25415 - load_blob_to_snowflake - STEP_START - Started execution of step "load_blob_to_snowflake".
[32m2025-07-03 10:14:19 +0000[0m - dagster - [34mERROR[0m - [31m__ASSET_JOB - 2c60d167-0d55-4a4e-bd1f-c8c659d0e20e - 25415 - load_blob_to_snowflake - STEP_FAILURE - Execution of step "load_blob_to_snowflake" failed.

dagster._core.errors.DagsterExecutionStepExecutionError: Error occurred while executing op "load_blob_to_snowflake"::

TypeError: 'NoneType' object is not subscriptable

Stack Trace:
  File "/usr/local/python/3.12.1/lib/python3.12/site-packages/dagster/_core/execution/plan/utils.py", line 57, in op_execution_error_boundary
    yield
  File "/usr/local/python/3.12.1/lib/python3.12/site-packages/dagster/_utils/__init__.py", line 392, in iterate_with_context
    next_output = next(iterator)
                  ^^^^^^^^^^^^^^
  File "/usr/local/python/3.12.1/lib/python3.12/site-packages/dagster/_core/execution/plan/compute_generator.py", line 137, in _coerce_op_compute_fn_to_iterator
    result = invoke_compute_fn(
             ^^^^^^^^^^^^^^^^^^
  File "/usr/local/python/3.12.1/lib/python3.12/site-packages/dagster/_core/execution/plan/compute_generator.py", line 117, in invoke_compute_fn
    return fn(context, **args_to_pass) if context_arg_provided else fn(**args_to_pass)
           ^^^^^^^^^^^^^^^^^^^^^^^^^^^
  File "/workspaces/Wheather_project/weather_proj/weather_proj/assets.py", line 49, in load_blob_to_snowflake
    blob_name = context.op_config["blob_name"]
                ~~~~~~~~~~~~~~~~~^^^^^^^^^^^^^
[0m
