[32m2025-07-03 10:32:47 +0000[0m - dagster - [34mDEBUG[0m - load_weather_to_snowflake_job - 97bc2b21-39d1-4fed-8b4f-d99192d12eb9 - 53670 - LOGS_CAPTURED - Started capturing logs in process (pid: 53670).
[32m2025-07-03 10:32:47 +0000[0m - dagster - [34mDEBUG[0m - load_weather_to_snowflake_job - 97bc2b21-39d1-4fed-8b4f-d99192d12eb9 - 53670 - load_blob_to_snowflake - STEP_START - Started execution of step "load_blob_to_snowflake".
[32m2025-07-03 10:32:47 +0000[0m - dagster - [34mERROR[0m - [31mload_weather_to_snowflake_job - 97bc2b21-39d1-4fed-8b4f-d99192d12eb9 - 53670 - load_blob_to_snowflake - STEP_FAILURE - Execution of step "load_blob_to_snowflake" failed.

dagster._core.errors.DagsterExecutionStepExecutionError: Error occurred while executing op "load_blob_to_snowflake"::

ValueError: Please specify a container name and blob name.

Stack Trace:
  File "/usr/local/python/3.12.1/lib/python3.12/site-packages/dagster/_core/execution/plan/utils.py", line 57, in op_execution_error_boundary
    yield
  File "/usr/local/python/3.12.1/lib/python3.12/site-packages/dagster/_utils/__init__.py", line 392, in iterate_with_context
    next_output = next(iterator)
                  ^^^^^^^^^^^^^^
  File "/usr/local/python/3.12.1/lib/python3.12/site-packages/dagster/_core/execution/plan/compute_generator.py", line 137, in _coerce_op_compute_fn_to_iterator
    result = invoke_compute_fn(
             ^^^^^^^^^^^^^^^^^^
  File "/usr/local/python/3.12.1/lib/python3.12/site-packages/dagster/_core/execution/plan/compute_generator.py", line 117, in invoke_compute_fn
    return fn(context, **args_to_pass) if context_arg_provided else fn(**args_to_pass)
           ^^^^^^^^^^^^^^^^^^^^^^^^^^^
  File "/workspaces/Wheather_project/weather_proj/weather_proj/ops.py", line 15, in load_blob_to_snowflake
    blob_client = blob_service.get_container_client(container).get_blob_client(blob_name)
                  ^^^^^^^^^^^^^^^^^^^^^^^^^^^^^^^^^^^^^^^^^^^^^^^^^^^^^^^^^^^^^^^^^^^^^^^
  File "/usr/local/python/3.12.1/lib/python3.12/site-packages/azure/storage/blob/_container_client.py", line 1614, in get_blob_client
    return BlobClient(
           ^^^^^^^^^^^
  File "/usr/local/python/3.12.1/lib/python3.12/site-packages/azure/storage/blob/_blob_client.py", line 170, in __init__
    parsed_url, sas_token, path_snapshot = _parse_url(
                                           ^^^^^^^^^^^
  File "/usr/local/python/3.12.1/lib/python3.12/site-packages/azure/storage/blob/_blob_client_helpers.py", line 79, in _parse_url
    raise ValueError("Please specify a container name and blob name.")
[0m
